<?xml version="1.0" encoding="utf-8"?>
<!-- This URDF was automatically created by SolidWorks to URDF Exporter! Originally created by Stephen Brawner (brawner@gmail.com) 
     Commit Version: 1.6.0-4-g7f85cfe  Build Version: 1.6.7995.38578
     For more information, please see http://wiki.ros.org/sw_urdf_exporter -->
<robot
  name="arm_urdf_attempt_1">
  <link
    name="base_link">
    <inertial>
      <origin
        xyz="-2.15105711021124E-16 4.16333634234434E-17 0.0236699430726066"
        rpy="0 0 0" />
      <mass
        value="0.303577466401528" />
      <inertia
        ixx="0.000487283345605958"
        ixy="-4.0604328814282E-18"
        ixz="-2.49902423019563E-19"
        iyy="0.000487283345605958"
        iyz="-4.11872843731475E-19"
        izz="0.000943263997918369" />
    </inertial>
    <visual>
      <origin
        xyz="0 0 0"
        rpy="0 0 0" />
      <geometry>
        <mesh
          filename="package://arm_urdf_attempt_1/meshes/base_link.STL" />
      </geometry>
      <material
        name="">
        <color
          rgba="0.898039215686275 0.917647058823529 0.929411764705882 1" />
      </material>
    </visual>
    <collision>
      <origin
        xyz="0 0 0"
        rpy="0 0 0" />
      <geometry>
        <mesh
          filename="package://arm_urdf_attempt_1/meshes/base_link.STL" />
      </geometry>
    </collision>
  </link>
  <link
    name="shoulder_link">
    <inertial>
      <origin
        xyz="-0.00108589432988627 0.00104453818881597 -0.0115032054388252"
        rpy="0 0 0" />
      <mass
        value="0.578300307697333" />
      <inertia
        ixx="0.000457491664954998"
        ixy="4.40695079130614E-08"
        ixz="-5.24944352494752E-07"
        iyy="0.000466714143740786"
        iyz="-3.9888872616818E-05"
        izz="0.000492278897171974" />
    </inertial>
    <visual>
      <origin
        xyz="0 0 0"
        rpy="0 0 0" />
      <geometry>
        <mesh
          filename="package://arm_urdf_attempt_1/meshes/shoulder_link.STL" />
      </geometry>
      <material
        name="">
        <color
          rgba="0.792156862745098 0.819607843137255 0.933333333333333 1" />
      </material>
    </visual>
    <collision>
      <origin
        xyz="0 0 0"
        rpy="0 0 0" />
      <geometry>
        <mesh
          filename="package://arm_urdf_attempt_1/meshes/shoulder_link.STL" />
      </geometry>
    </collision>
  </link>
  <joint
    name="base-rotation"
    type="continuous">
    <origin
      xyz="0 0 0.1238"
      rpy="1.5708 0 0" />
    <parent
      link="base_link" />
    <child
      link="shoulder_link" />
    <axis
      xyz="0 1 0" />
  </joint>
  <link
    name="upper_arm_link">
    <inertial>
      <origin
        xyz="-0.242503153942016 -5.77669424302318E-07 -0.0253615987772052"
        rpy="0 0 0" />
      <mass
        value="0.514292774377408" />
      <inertia
        ixx="0.000595642413199703"
        ixy="1.22950190154906E-08"
        ixz="-5.13167613690387E-08"
        iyy="0.00505803319818708"
        iyz="-1.22192589471583E-08"
        izz="0.00552655986550431" />
    </inertial>
    <visual>
      <origin
        xyz="0 0 0"
        rpy="0 0 0" />
      <geometry>
        <mesh
          filename="package://arm_urdf_attempt_1/meshes/upper_arm_link.STL" />
      </geometry>
      <material
        name="">
        <color
          rgba="0.792156862745098 0.819607843137255 0.933333333333333 1" />
      </material>
    </visual>
    <collision>
      <origin
        xyz="0 0 0"
        rpy="0 0 0" />
      <geometry>
        <mesh
          filename="package://arm_urdf_attempt_1/meshes/upper_arm_link.STL" />
      </geometry>
    </collision>
  </link>
  <joint
    name="shoulder"
    type="continuous">
    <origin
      xyz="0 0.485 0.1258"
      rpy="0 0 1.5708" />
    <parent
      link="shoulder_link" />
    <child
      link="upper_arm_link" />
    <axis
      xyz="0 0 1" />
  </joint>
  <link
    name="fore_arm_link">
    <inertial>
      <origin
        xyz="-0.280503991164541 0.0290165992543888 -0.0307353704762849"
        rpy="0 0 0" />
      <mass
        value="0.878694547843131" />
      <inertia
        ixx="0.00111677818316444"
        ixy="-3.95763823988894E-08"
        ixz="3.11645354052697E-06"
        iyy="0.00322319211600831"
        iyz="0.000293141391325471"
        izz="0.00350482047067742" />
    </inertial>
    <visual>
      <origin
        xyz="0 0 0"
        rpy="0 0 0" />
      <geometry>
        <mesh
          filename="package://arm_urdf_attempt_1/meshes/fore_arm_link.STL" />
      </geometry>
      <material
        name="">
        <color
          rgba="0.792156862745098 0.819607843137255 0.933333333333333 1" />
      </material>
    </visual>
    <collision>
      <origin
        xyz="0 0 0"
        rpy="0 0 0" />
      <geometry>
        <mesh
          filename="package://arm_urdf_attempt_1/meshes/fore_arm_link.STL" />
      </geometry>
    </collision>
  </link>
  <joint
    name="elbow"
    type="continuous">
    <origin
      xyz="0.468 0.05103 -0.1004"
      rpy="-0.0069564 0 0" />
    <parent
      link="upper_arm_link" />
    <child
      link="fore_arm_link" />
    <axis
      xyz="0 0.0069564 -0.99998" />
  </joint>
  <link
    name="wrist_a_link">
    <inertial>
      <origin
        xyz="4.54063678101413E-06 0.00400994549583587 0.0309332485687411"
        rpy="0 0 0" />
      <mass
        value="0.13211366619723" />
      <inertia
        ixx="9.58431968283196E-05"
        ixy="7.56409048134941E-08"
        ixz="-4.74004957401875E-10"
        iyy="0.000105476440501887"
        iyz="2.20006728961237E-08"
        izz="9.54267891151975E-05" />
    </inertial>
    <visual>
      <origin
        xyz="0 0 0"
        rpy="0 0 0" />
      <geometry>
        <mesh
          filename="package://arm_urdf_attempt_1/meshes/wrist_a_link.STL" />
      </geometry>
      <material
        name="">
        <color
          rgba="0.792156862745098 0.819607843137255 0.933333333333333 1" />
      </material>
    </visual>
    <collision>
      <origin
        xyz="0 0 0"
        rpy="0 0 0" />
      <geometry>
        <mesh
          filename="package://arm_urdf_attempt_1/meshes/wrist_a_link.STL" />
      </geometry>
    </collision>
  </link>
  <joint
    name="j4"
    type="continuous">
    <origin
      xyz="0 0 0.10007"
      rpy="-1.5708 0 0" />
    <parent
      link="fore_arm_link" />
    <child
      link="wrist_a_link" />
    <axis
      xyz="0 1 0" />
  </joint>
  <link
    name="wrist_b_link">
    <inertial>
      <origin
        xyz="4.54060680697352E-06 0.0040099453520431 0.0309332434107732"
        rpy="0 0 0" />
      <mass
        value="0.132113663462452" />
      <inertia
        ixx="9.58431913908768E-05"
        ixy="7.56411401322342E-08"
        ixz="-4.73200171281675E-10"
        iyy="0.000105476434923144"
        iyz="2.20007118533406E-08"
        izz="9.54267869746594E-05" />
    </inertial>
    <visual>
      <origin
        xyz="0 0 0"
        rpy="0 0 0" />
      <geometry>
        <mesh
          filename="package://arm_urdf_attempt_1/meshes/wrist_b_link.STL" />
      </geometry>
      <material
        name="">
        <color
          rgba="0.792156862745098 0.819607843137255 0.933333333333333 1" />
      </material>
    </visual>
    <collision>
      <origin
        xyz="0 0 0"
        rpy="0 0 0" />
      <geometry>
        <mesh
          filename="package://arm_urdf_attempt_1/meshes/wrist_b_link.STL" />
      </geometry>
    </collision>
  </link>
  <joint
    name="j5"
    type="continuous">
    <origin
      xyz="0 0 0.10225"
      rpy="-1.5708 0 -1.5708" />
    <parent
      link="wrist_a_link" />
    <child
      link="wrist_b_link" />
    <axis
      xyz="0 1 0" />
  </joint>
  <link
    name="end_effector_link">
    <inertial>
      <origin
        xyz="0.0113412558418731 -0.0197007819555739 0.0633724532226339"
        rpy="0 0 0" />
      <mass
        value="0.386619544800973" />
      <inertia
        ixx="0.000279649493302485"
        ixy="-3.2978765110518E-07"
        ixz="2.91527532510257E-07"
        iyy="0.000570040658440387"
        iyz="5.22687392642322E-06"
        izz="0.000424494038173486" />
    </inertial>
    <visual>
      <origin
        xyz="0 0 0"
        rpy="0 0 0" />
      <geometry>
        <mesh
          filename="package://arm_urdf_attempt_1/meshes/end_effector_link.STL" />
      </geometry>
      <material
        name="">
        <color
          rgba="0.792156862745098 0.819607843137255 0.933333333333333 1" />
      </material>
    </visual>
    <collision>
      <origin
        xyz="0 0 0"
        rpy="0 0 0" />
      <geometry>
        <mesh
          filename="package://arm_urdf_attempt_1/meshes/end_effector_link.STL" />
      </geometry>
    </collision>
  </link>
  <joint
    name="j6"
    type="continuous">
    <origin
      xyz="0 0 0.10125"
      rpy="0 0 0" />
    <parent
      link="wrist_b_link" />
    <child
      link="end_effector_link" />
    <axis
      xyz="0 0 -1" />
  </joint>
</robot>
